Workbook

Sheet DATA
F1: QUARTER OPTIONS: | G1: Q1 2024
G2: Q2 2024
G3: Q3 2024
G4: Q4 2024
B5: ACTIVE TABLE FOR SELECTED | E5: ='DASHBOARD!!'!D5 -> Q2 2024
C8: =E5 -> Q2 2024
C9: {=SWITCH($E$5,$G$1,C26,$G$2,C37,$G$3,C48,$G$4,C59)} -> April | D9: {=SWITCH($E$5,$G$1,D26,$G$2,D37,$G$3,D48,$G$4,D59)} -> May | E9: {=SWITCH($E$5,$G$1,E26,$G$2,E37,$G$3,E48,$G$4,E59)} -> June | F9: {=SWITCH($E$5,$G$1,F26,$G$2,F37,$G$3,F48,$G$4,F59)} -> April | G9: {=SWITCH($E$5,$G$1,G26,$G$2,G37,$G$3,G48,$G$4,G59)} -> May | H9: {=SWITCH($E$5,$G$1,H26,$G$2,H37,$G$3,H48,$G$4,H59)} -> June | I9: {=SWITCH($E$5,$G$1,I26,$G$2,I37,$G$3,I48,$G$4,I59)} -> April | J9: {=SWITCH($E$5,$G$1,J26,$G$2,J37,$G$3,J48,$G$4,J59)} -> May | ... AR9: {=SWITCH($E$5,$G$1,AR26,$G$2,AR37,$G$3,AR48,$G$4,AR59)} -> June
C10: {=SWITCH($E$5,$G$1,C27,$G$2,C38,$G$3,C49,$G$4,C60)} -> Revenue | D10: {=SWITCH($E$5,$G$1,D27,$G$2,D38,$G$3,D49,$G$4,D60)} -> Revenue | E10: {=SWITCH($E$5,$G$1,E27,$G$2,E38,$G$3,E49,$G$4,E60)} -> Revenue | F10: {=SWITCH($E$5,$G$1,F27,$G$2,F38,$G$3,F49,$G$4,F60)} -> Target Revenue | G10: {=SWITCH($E$5,$G$1,G27,$G$2,G38,$G$3,G49,$G$4,G60)} -> Target Revenue | H10: {=SWITCH($E$5,$G$1,H27,$G$2,H38,$G$3,H49,$G$4,H60)} -> Target Revenue | I10: {=SWITCH($E$5,$G$1,I27,$G$2,I38,$G$3,I49,$G$4,I60)} -> Previous Year Revenue | J10: {=SWITCH($E$5,$G$1,J27,$G$2,J38,$G$3,J49,$G$4,J60)} -> Previous Year Revenue | ... AR10: {=SWITCH($E$5,$G$1,AR27,$G$2,AR38,$G$3,AR49,$G$4,AR60)} -> Target Revenue per Customer
B11: Jacob | C11: {=SWITCH($E$5, $G$1, C28, $G$2, C39, $G$3, C50, $G$4, C61)} -> 130000 | D11: {=SWITCH($E$5, $G$1, D28, $G$2, D39, $G$3, D50, $G$4, D61)} -> 135000 | E11: {=SWITCH($E$5, $G$1, E28, $G$2, E39, $G$3, E50, $G$4, E61)} -> 150000 | F11: {=SWITCH($E$5, $G$1, F28, $G$2, F39, $G$3, F50, $G$4, F61)} -> 150000 | G11: {=SWITCH($E$5, $G$1, G28, $G$2, G39, $G$3, G50, $G$4, G61)} -> 160000 | H11: {=SWITCH($E$5, $G$1, H28, $G$2, H39, $G$3, H50, $G$4, H61)} -> 140000 | I11: {=SWITCH($E$5, $G$1, I28, $G$2, I39, $G$3, I50, $G$4, I61)} -> 125000 | J11: {=SWITCH($E$5, $G$1, J28, $G$2, J39, $G$3, J50, $G$4, J61)} -> 160000 | ... AR11: {=SWITCH($E$5, $G$1, AR28, $G$2, AR39, $G$3, AR50, $G$4, AR61)} -> 2600
B12: Arnold | C12: {=SWITCH($E$5, $G$1, C29, $G$2, C40, $G$3, C51, $G$4, C62)} -> 175000 | D12: {=SWITCH($E$5, $G$1, D29, $G$2, D40, $G$3, D51, $G$4, D62)} -> 155000 | E12: {=SWITCH($E$5, $G$1, E29, $G$2, E40, $G$3, E51, $G$4, E62)} -> 190000 | F12: {=SWITCH($E$5, $G$1, F29, $G$2, F40, $G$3, F51, $G$4, F62)} -> 150000 | G12: {=SWITCH($E$5, $G$1, G29, $G$2, G40, $G$3, G51, $G$4, G62)} -> 160000 | H12: {=SWITCH($E$5, $G$1, H29, $G$2, H40, $G$3, H51, $G$4, H62)} -> 140000 | I12: {=SWITCH($E$5, $G$1, I29, $G$2, I40, $G$3, I51, $G$4, I62)} -> 145000 | J12: {=SWITCH($E$5, $G$1, J29, $G$2, J40, $G$3, J51, $G$4, J62)} -> 125000 | ... AR12: {=SWITCH($E$5, $G$1, AR29, $G$2, AR40, $G$3, AR51, $G$4, AR62)} -> 2600
B13: Naomi | C13: {=SWITCH($E$5, $G$1, C30, $G$2, C41, $G$3, C52, $G$4, C63)} -> 180000 | D13: {=SWITCH($E$5, $G$1, D30, $G$2, D41, $G$3, D52, $G$4, D63)} -> 145000 | E13: {=SWITCH($E$5, $G$1, E30, $G$2, E41, $G$3, E52, $G$4, E63)} -> 155000 | F13: {=SWITCH($E$5, $G$1, F30, $G$2, F41, $G$3, F52, $G$4, F63)} -> 150000 | G13: {=SWITCH($E$5, $G$1, G30, $G$2, G41, $G$3, G52, $G$4, G63)} -> 160000 | H13: {=SWITCH($E$5, $G$1, H30, $G$2, H41, $G$3, H52, $G$4, H63)} -> 140000 | I13: {=SWITCH($E$5, $G$1, I30, $G$2, I41, $G$3, I52, $G$4, I63)} -> 155000 | J13: {=SWITCH($E$5, $G$1, J30, $G$2, J41, $G$3, J52, $G$4, J63)} -> 130000 | ... AR13: {=SWITCH($E$5, $G$1, AR30, $G$2, AR41, $G$3, AR52, $G$4, AR63)} -> 2600
B14: David | C14: {=SWITCH($E$5, $G$1, C31, $G$2, C42, $G$3, C53, $G$4, C64)} -> 160000 | D14: {=SWITCH($E$5, $G$1, D31, $G$2, D42, $G$3, D53, $G$4, D64)} -> 180000 | E14: {=SWITCH($E$5, $G$1, E31, $G$2, E42, $G$3, E53, $G$4, E64)} -> 175000 | F14: {=SWITCH($E$5, $G$1, F31, $G$2, F42, $G$3, F53, $G$4, F64)} -> 150000 | G14: {=SWITCH($E$5, $G$1, G31, $G$2, G42, $G$3, G53, $G$4, G64)} -> 160000 | H14: {=SWITCH($E$5, $G$1, H31, $G$2, H42, $G$3, H53, $G$4, H64)} -> 140000 | I14: {=SWITCH($E$5, $G$1, I31, $G$2, I42, $G$3, I53, $G$4, I64)} -> 145000 | J14: {=SWITCH($E$5, $G$1, J31, $G$2, J42, $G$3, J53, $G$4, J64)} -> 140000 | ... AR14: {=SWITCH($E$5, $G$1, AR31, $G$2, AR42, $G$3, AR53, $G$4, AR64)} -> 2600
B15: Ariel | C15: {=SWITCH($E$5, $G$1, C32, $G$2, C43, $G$3, C54, $G$4, C65)} -> 205000 | D15: {=SWITCH($E$5, $G$1, D32, $G$2, D43, $G$3, D54, $G$4, D65)} -> 195000 | E15: {=SWITCH($E$5, $G$1, E32, $G$2, E43, $G$3, E54, $G$4, E65)} -> 125000 | F15: {=SWITCH($E$5, $G$1, F32, $G$2, F43, $G$3, F54, $G$4, F65)} -> 150000 | G15: {=SWITCH($E$5, $G$1, G32, $G$2, G43, $G$3, G54, $G$4, G65)} -> 160000 | H15: {=SWITCH($E$5, $G$1, H32, $G$2, H43, $G$3, H54, $G$4, H65)} -> 140000 | I15: {=SWITCH($E$5, $G$1, I32, $G$2, I43, $G$3, I54, $G$4, I65)} -> 125000 | J15: {=SWITCH($E$5, $G$1, J32, $G$2, J43, $G$3, J54, $G$4, J65)} -> 150000 | ... AR15: {=SWITCH($E$5, $G$1, AR32, $G$2, AR43, $G$3, AR54, $G$4, AR65)} -> 2600
B16: TOTAL | C16: =SUM(C11:C15) -> 850000 | D16: =SUM(D11:D15) -> 810000 | E16: =SUM(E11:E15) -> 795000 | F16: =SUM(F11:F15) -> 750000 | G16: =SUM(G11:G15) -> 800000 | H16: =SUM(H11:H15) -> 700000 | I16: =SUM(I11:I15) -> 695000 | J16: =SUM(J11:J15) -> 705000 | ... Z16: =SUM(Z11:Z15) -> 35500 | AA16: =AVERAGE(AA11:AA15) -> 370.694 | AB16: =AVERAGE(AB11:AB15) -> 406.71 | AC16: =AVERAGE(AC11:AC15) -> 417.432 | AD16: =AVERAGE(AD11:AD15) -> 400 | AE16: =AVERAGE(AE11:AE15) -> 350 | AF16: =AVERAGE(AF11:AF15) -> 350 | AG16: =AVERAGE(AG11:AG15) -> 377.4 | AH16: =AVERAGE(AH11:AH15) -> 354 | ... AR16: =AVERAGE(AR11:AR15) -> 2600
B18: TOTAL REVENUE PER YEAR | D18: =SUM(C33:E33,C44:E44,C55:E55,C66:E66) -> 9271500
B19: TOTAL CUSTOMERS PER YEAR | D19: =SUM(L33:N33,L44:N44,L55:N55,L66:N66) -> 3799
B20: NEW CUSTOMERS PER YEAR | D20: =SUM(R33:T33,R44:T44,R55:T55,R66:T66) -> 1228
B21: REVENUE PER CUSTOMER | D21: =D18/D19 -> 2440.5107
C25: Q1 2023
C26: January | D26: February | E26: March | F26: January | G26: February | H26: March | I26: January | J26: February | K26: March | L26: January | M26: February | N26: March | O26: January | P26: February | Q26: March | R26: January | S26: February | T26: March | U26: January | V26: February | W26: March | X26: January | Y26: February | Z26: March | AA26: January | AB26: February | AC26: March | AD26: January | AE26: February | AF26: March | AG26: January | AH26: February | AI26: March | AJ26: January | AK26: February | AL26: March | AM26: January | AN26: February | AO26: March | AP26: January | AQ26: February | AR26: March
C27: Revenue | D27: Revenue | E27: Revenue | F27: Target Revenue | G27: Target Revenue | H27: Target Revenue | I27: Previous Year Revenue | J27: Previous Year Revenue | K27: Previous Year Revenue | L27: Number of Customers | M27: Number of Customers | N27: Number of Customers | O27: Number of New Customers Target | P27: Number of New Customers Target | Q27: Number of New Customers Target | R27: Number of New Customers | S27: Number of New Customers | T27: Number of New Customers | U27: Number of New Customers Previous Year | V27: Number of New Customers Previous Year | W27: Number of New Customers Previous Year | X27: Customer Acquisition Costs | Y27: Customer Acquisition Costs | Z27: Customer Acquisition Costs | AA27: Customer AC (per customer) | AB27: Customer AC (per customer) | AC27: Customer AC (per customer) | AD27: Customer AC (per customer) Target | AE27: Customer AC (per customer) Target | AF27: Customer AC (per customer) Target | AG27: Customer Aquis. Costs (per customer) PY | AH27: Customer Aquis. Costs (per customer) PY | AI27: Customer Aquis. Costs (per customer) PY | AJ27: Revenue per Customer | AK27: Revenue per Customer | AL27: Revenue per Customer | AM27: Revenue per Customer PY | AN27: Revenue per Customer PY | AO27: Revenue per Customer PY | AP27: Target Revenue per Customer | AQ27: Target Revenue per Customer | AR27: Target Revenue per Customer
B28: Jacob | C28: 135000 | D28: 130000 | E28: 160000 | F28: 150000 | G28: 140000 | H28: 150000 | I28: 115000 | J28: 140000 | K28: 160000 | L28: 57 | M28: 58 | N28: 63 | O28: 25 | P28: 20 | Q28: 25 | R28: 10 | S28: 11 | T28: 18 | U28: 9 | V28: 12 | W28: 14 | X28: 4200 | Y28: 5000 | Z28: 5500 | AA28: 420 | AB28: 454.55 | AC28: 305.56 | AD28: 350 | AE28: 350 | AF28: 350 | AG28: 400 | AH28: 385 | AI28: 390 | AJ28: 2192.98 | AK28: 2241.38 | AL28: 2539.68 | AM28: 2200 | AN28: 2100 | AO28: 2400 | AP28: 2500 | AQ28: 2600 | AR28: 2400
B29: Arnold | C29: 170000 | D29: 160000 | E29: 185000 | F29: 150000 | G29: 140000 | H29: 150000 | I29: 160000 | J29: 130000 | K29: 125000 | L29: 74 | M29: 70 | N29: 74 | O29: 25 | P29: 20 | Q29: 25 | R29: 22 | S29: 23 | T29: 26 | U29: 17 | V29: 24 | W29: 22 | X29: 7800 | Y29: 10000 | Z29: 9000 | AA29: 354.55 | AB29: 434.78 | AC29: 346.15 | AD29: 350 | AE29: 350 | AF29: 350 | AG29: 402 | AH29: 290 | AI29: 380 | AJ29: 2432.43 | AK29: 2285.71 | AL29: 2500 | AM29: 2100 | AN29: 2200 | AO29: 2300 | AP29: 2500 | AQ29: 2600 | AR29: 2400
B30: Naomi | C30: 175000 | D30: 135000 | E30: 145000 | F30: 150000 | G30: 140000 | H30: 150000 | I30: 170000 | J30: 145000 | K30: 130000 | L30: 70 | M30: 55 | N30: 61 | O30: 25 | P30: 20 | Q30: 25 | R30: 35 | S30: 20 | T30: 17 | U30: 36 | V30: 25 | W30: 21 | X30: 13200 | Y30: 9500 | Z30: 8300 | AA30: 377.14 | AB30: 475 | AC30: 488.24 | AD30: 350 | AE30: 350 | AF30: 350 | AG30: 350 | AH30: 385 | AI30: 352 | AJ30: 2428.57 | AK30: 2454.55 | AL30: 2377.05 | AM30: 2500 | AN30: 2500 | AO30: 2300 | AP30: 2500 | AQ30: 2600 | AR30: 2400
B31: David | C31: 156000 | D31: 175000 | E31: 155000 | F31: 150000 | G31: 140000 | H31: 150000 | I31: 165000 | J31: 155000 | K31: 140000 | L31: 66 | M31: 68 | N31: 63 | O31: 25 | P31: 20 | Q31: 25 | R31: 18 | S31: 14 | T31: 24 | U31: 14 | V31: 25 | W31: 22 | X31: 6500 | Y31: 9000 | Z31: 8500 | AA31: 361.11 | AB31: 642.86 | AC31: 354.17 | AD31: 350 | AE31: 350 | AF31: 350 | AG31: 350 | AH31: 360 | AI31: 388 | AJ31: 2272.73 | AK31: 2573.53 | AL31: 2460.32 | AM31: 2200 | AN31: 2600 | AO31: 2400 | AP31: 2500 | AQ31: 2600 | AR31: 2400
B32: Ariel | C32: 135500 | D32: 190000 | E32: 140000 | F32: 150000 | G32: 140000 | H32: 150000 | I32: 155000 | J32: 120000 | K32: 150000 | L32: 71 | M32: 62 | N32: 51 | O32: 25 | P32: 20 | Q32: 25 | R32: 33 | S32: 20 | T32: 16 | U32: 20 | V32: 25 | W32: 24 | X32: 12100 | Y32: 10800 | Z32: 10500 | AA32: 366.67 | AB32: 540 | AC32: 656.25 | AD32: 350 | AE32: 350 | AF32: 350 | AG32: 385 | AH32: 350 | AI32: 406 | AJ32: 1901.41 | AK32: 3064.52 | AL32: 2745.1 | AM32: 2100 | AN32: 2800 | AO32: 2700 | AP32: 2500 | AQ32: 2600 | AR32: 2400
B33: TOTAL | C33: =SUM(C28:C32) -> 771500 | D33: =SUM(D28:D32) -> 790000 | E33: =SUM(E28:E32) -> 785000 | F33: =SUM(F28:F32) -> 750000 | G33: =SUM(G28:G32) -> 700000 | H33: =SUM(H28:H32) -> 750000 | I33: =SUM(I28:I32) -> 765000 | J33: =SUM(J28:J32) -> 690000 | ... Z33: =SUM(Z28:Z32) -> 41800 | AA33: =AVERAGE(AA28:AA32) -> 375.894 | AB33: =AVERAGE(AB28:AB32) -> 509.438 | AC33: =AVERAGE(AC28:AC32) -> 430.074 | AD33: =AVERAGE(AD28:AD32) -> 350 | AE33: =AVERAGE(AE28:AE32) -> 350 | AF33: =AVERAGE(AF28:AF32) -> 350 | AG33: =AVERAGE(AG28:AG32) -> 377.4 | AH33: =AVERAGE(AH28:AH32) -> 354 | ... AR33: =AVERAGE(AR28:AR32) -> 2400
C36: Q2 2023
C37: April | D37: May | E37: June | F37: April | G37: May | H37: June | I37: April | J37: May | K37: June | L37: April | M37: May | N37: June | O37: April | P37: May | Q37: June | R37: April | S37: May | T37: June | U37: April | V37: May | W37: June | X37: April | Y37: May | Z37: June | AA37: April | AB37: May | AC37: June | AD37: April | AE37: May | AF37: June | AG37: April | AH37: May | AI37: June | AJ37: April | AK37: May | AL37: June | AM37: April | AN37: May | AO37: June | AP37: April | AQ37: May | AR37: June
C38: Revenue | D38: Revenue | E38: Revenue | F38: Target Revenue | G38: Target Revenue | H38: Target Revenue | I38: Previous Year Revenue | J38: Previous Year Revenue | K38: Previous Year Revenue | L38: Number of Customers | M38: Number of Customers | N38: Number of Customers | O38: Number of New Customers Target | P38: Number of New Customers Target | Q38: Number of New Customers Target | R38: Number of New Customers | S38: Number of New Customers | T38: Number of New Customers | U38: Number of New Customers Previous Year | V38: Number of New Customers Previous Year | W38: Number of New Customers Previous Year | X38: Customer Acquisition Costs | Y38: Customer Acquisition Costs | Z38: Customer Acquisition Costs | AA38: Customer AC (per customer) | AB38: Customer AC (per customer) | AC38: Customer AC (per customer) | AD38: Customer AC (per customer) Target | AE38: Customer AC (per customer) Target | AF38: Customer AC (per customer) Target | AG38: Customer Aquis. Costs (per customer) PY | AH38: Customer Aquis. Costs (per customer) PY | AI38: Customer Aquis. Costs (per customer) PY | AJ38: Revenue per Customer | AK38: Revenue per Customer | AL38: Revenue per Customer | AM38: Revenue per Customer PY | AN38: Revenue per Customer PY | AO38: Revenue per Customer PY | AP38: Target Revenue per Customer | AQ38: Target Revenue per Customer | AR38: Target Revenue per Customer
B39: Jacob | C39: 130000 | D39: 135000 | E39: 150000 | F39: 150000 | G39: 160000 | H39: 140000 | I39: 125000 | J39: 160000 | K39: 135000 | L39: 58 | M39: 63 | N39: 55 | O39: 30 | P39: 30 | Q39: 25 | R39: 12 | S39: 25 | T39: 11 | U39: 11 | V39: 21 | W39: 14 | X39: 5000 | Y39: 4500 | Z39: 5000 | AA39: 416.67 | AB39: 180 | AC39: 454.55 | AD39: 400 | AE39: 350 | AF39: 350 | AG39: 400 | AH39: 385 | AI39: 390 | AJ39: 2068.97 | AK39: 2142.86 | AL39: 2727.27 | AM39: 2100 | AN39: 2000 | AO39: 2600 | AP39: 2700 | AQ39: 2500 | AR39: 2600
B40: Arnold | C40: 175000 | D40: 155000 | E40: 190000 | F40: 150000 | G40: 160000 | H40: 140000 | I40: 145000 | J40: 125000 | K40: 125000 | L40: 70 | M40: 74 | N40: 65 | O40: 30 | P40: 30 | Q40: 25 | R40: 26 | S40: 18 | T40: 23 | U40: 17 | V40: 18 | W40: 15 | X40: 9800 | Y40: 9800 | Z40: 6500 | AA40: 376.92 | AB40: 544.44 | AC40: 282.61 | AD40: 400 | AE40: 350 | AF40: 350 | AG40: 402 | AH40: 290 | AI40: 380 | AJ40: 2500 | AK40: 2094.59 | AL40: 2923.08 | AM40: 2200 | AN40: 2000 | AO40: 2200 | AP40: 2700 | AQ40: 2500 | AR40: 2600
B41: Naomi | C41: 180000 | D41: 145000 | E41: 155000 | F41: 150000 | G41: 160000 | H41: 140000 | I41: 155000 | J41: 130000 | K41: 125000 | L41: 55 | M41: 61 | N41: 44 | O41: 30 | P41: 30 | Q41: 25 | R41: 31 | S41: 25 | T41: 20 | U41: 25 | V41: 21 | W41: 22 | X41: 9500 | Y41: 10200 | Z41: 8000 | AA41: 306.45 | AB41: 408 | AC41: 400 | AD41: 400 | AE41: 350 | AF41: 350 | AG41: 350 | AH41: 385 | AI41: 352 | AJ41: 3272.73 | AK41: 2377.05 | AL41: 3522.73 | AM41: 3000 | AN41: 2200 | AO41: 2100 | AP41: 2700 | AQ41: 2500 | AR41: 2600
B42: David | C42: 160000 | D42: 180000 | E42: 175000 | F42: 150000 | G42: 160000 | H42: 140000 | I42: 145000 | J42: 140000 | K42: 160000 | L42: 68 | M42: 63 | N42: 50 | O42: 30 | P42: 30 | Q42: 25 | R42: 28 | S42: 15 | T42: 14 | U42: 17 | V42: 18 | W42: 21 | X42: 9000 | Y42: 5600 | Z42: 7000 | AA42: 321.43 | AB42: 373.33 | AC42: 500 | AD42: 400 | AE42: 350 | AF42: 350 | AG42: 350 | AH42: 360 | AI42: 388 | AJ42: 2352.94 | AK42: 2857.14 | AL42: 3500 | AM42: 2200 | AN42: 2450 | AO42: 3300 | AP42: 2700 | AQ42: 2500 | AR42: 2600
B43: Ariel | C43: 205000 | D43: 195000 | E43: 125000 | F43: 150000 | G43: 160000 | H43: 140000 | I43: 125000 | J43: 150000 | K43: 145000 | L43: 62 | M43: 51 | N43: 35 | O43: 30 | P43: 30 | Q43: 25 | R43: 25 | S43: 18 | T43: 20 | U43: 20 | V43: 13 | W43: 20 | X43: 10800 | Y43: 9500 | Z43: 9000 | AA43: 432 | AB43: 527.78 | AC43: 450 | AD43: 400 | AE43: 350 | AF43: 350 | AG43: 385 | AH43: 350 | AI43: 406 | AJ43: 3306.45 | AK43: 3823.53 | AL43: 3571.43 | AM43: 2900 | AN43: 3100 | AO43: 3100 | AP43: 2700 | AQ43: 2500 | AR43: 2600
B44: TOTAL | C44: =SUM(C39:C43) -> 850000 | D44: =SUM(D39:D43) -> 810000 | E44: =SUM(E39:E43) -> 795000 | F44: =SUM(F39:F43) -> 750000 | G44: =SUM(G39:G43) -> 800000 | H44: =SUM(H39:H43) -> 700000 | I44: =SUM(I39:I43) -> 695000 | J44: =SUM(J39:J43) -> 705000 | ... Z44: =SUM(Z39:Z43) -> 35500 | AA44: =AVERAGE(AA39:AA43) -> 370.694 | AB44: =AVERAGE(AB39:AB43) -> 406.71 | AC44: =AVERAGE(AC39:AC43) -> 417.432 | AD44: =AVERAGE(AD39:AD43) -> 400 | AE44: =AVERAGE(AE39:AE43) -> 350 | AF44: =AVERAGE(AF39:AF43) -> 350 | AG44: =AVERAGE(AG39:AG43) -> 377.4 | AH44: =AVERAGE(AH39:AH43) -> 354 | ... AR44: =AVERAGE(AR39:AR43) -> 2600
C47: Q3 2023
C48: July | D48: August | E48: September | F48: July | G48: August | H48: September | I48: July | J48: August | K48: September | L48: July | M48: August | N48: September | O48: July | P48: August | Q48: September | R48: July | S48: August | T48: September | U48: July | V48: August | W48: September | X48: July | Y48: August | Z48: September | AA48: July | AB48: August | AC48: September | AD48: July | AE48: August | AF48: September | AG48: July | AH48: August | AI48: September | AJ48: July | AK48: August | AL48: September | AM48: July | AN48: August | AO48: September | AP48: July | AQ48: August | AR48: September
C49: Revenue | D49: Revenue | E49: Revenue | F49: Target Revenue | G49: Target Revenue | H49: Target Revenue | I49: Previous Year Revenue | J49: Previous Year Revenue | K49: Previous Year Revenue | L49: Number of Customers | M49: Number of Customers | N49: Number of Customers | O49: Number of New Customers Target | P49: Number of New Customers Target | Q49: Number of New Customers Target | R49: Number of New Customers | S49: Number of New Customers | T49: Number of New Customers | U49: Number of New Customers Previous Year | V49: Number of New Customers Previous Year | W49: Number of New Customers Previous Year | X49: Customer Acquisition Costs | Y49: Customer Acquisition Costs | Z49: Customer Acquisition Costs | AA49: Customer AC (per customer) | AB49: Customer AC (per customer) | AC49: Customer AC (per customer) | AD49: Customer AC (per customer) Target | AE49: Customer AC (per customer) Target | AF49: Customer AC (per customer) Target | AG49: Customer Aquis. Costs (per customer) PY | AH49: Customer Aquis. Costs (per customer) PY | AI49: Customer Aquis. Costs (per customer) PY | AJ49: Revenue per Customer | AK49: Revenue per Customer | AL49: Revenue per Customer | AM49: Revenue per Customer PY | AN49: Revenue per Customer PY | AO49: Revenue per Customer PY | AP49: Target Revenue per Customer | AQ49: Target Revenue per Customer | AR49: Target Revenue per Customer
B50: Jacob | C50: 150000 | D50: 145000 | E50: 145000 | F50: 160000 | G50: 145000 | H50: 160000 | I50: 160000 | J50: 125000 | K50: 145000 | L50: 55 | M50: 55 | N50: 60 | O50: 20 | P50: 25 | Q50: 35 | R50: 14 | S50: 18 | T50: 17 | U50: 21 | V50: 15 | W50: 11 | X50: 8000 | Y50: 6000 | Z50: 4000 | AA50: 571.43 | AB50: 333.33 | AC50: 235.29 | AD50: 350 | AE50: 450 | AF50: 350 | AG50: 400 | AH50: 385 | AI50: 390 | AJ50: 2909.09 | AK50: 2636.36 | AL50: 2416.67 | AM50: 2800 | AN50: 2500 | AO50: 2300 | AP50: 2200 | AQ50: 2300 | AR50: 2500
...

Sheet DASHBOARD!!
A1: KPI OVERVIEW
D5: Q2 2024
A6: Revenue Compared per year | L6: New Customers per year
A8: Revenue Actual VS Target | L8: New customers Actual VS Target
A10: Actual Revenue | C10: =SUM(DATA!C16:E16) -> 2455000 | L10: Actual new customers | N10: =SUM(DATA!R16:T16) -> 311
A14: Target Revenue | C14: =SUM(DATA!F16:H16) -> 2250000 | L14: Target new customers | N14: =SUM(DATA!O16:Q16) -> 425
A18: Target achivement | C18: =C10/C14 -> 1.0911111 | L18: Target achivement | N18: =N10/N14 -> 0.73176471
A23: Average Revenue Per Year | L23: Customer Acquisition costs per year
A25: Avg. Revenue per Customer | L25: Customer Acquisition Cost
A27: Actual Revenue Per Customer | C27: =SUM(DATA!AJ16:AL16) -> 8608.154 | L27: Actual CAC | N27: =SUM(DATA!AA16:AC16) -> 1194.836
A31: Target Revnue Per Customer | C31: =SUM(DATA!AP16:AR16) -> 7800 | L31: Target CAC | N31: =SUM(DATA!AD16:AF16) -> 1100
A35: Target achivement | C35: =C27/C31 -> 1.1036095 | L35: Target achivement | N35: =N27/N31 -> 1.0862145
